Workbook
Name cash_sweep_pct: Assumptions!$C$16
Name commitment_fee: Assumptions!$C$13
Name da_pct: Assumptions!$C$32
Name entry_multiple: Assumptions!$C$4
Name existing_cash: Assumptions!$C$23
Name existing_debt: Assumptions!$C$22
Name exit_multiple: Assumptions!$C$5
Name fin_fee_pct: Assumptions!$C$28
Name hold_years: Assumptions!$C$6
Name hurdle_irr: Assumptions!$C$36
Name ltm_ebitda: Operating_Model!$B$19
Name mezz_cash_rate: Assumptions!$C$18
Name mezz_pik_rate: Assumptions!$C$19
Name mezz_turns: Assumptions!$C$17
Name min_cash: Assumptions!$C$24
Name nwc_pct: Assumptions!$C$33
Name revolver_capacity: Assumptions!$C$11
Name revolver_rate: Assumptions!$C$12
Name tax_rate: Assumptions!$C$31
Name tlb_amort_pct: Assumptions!$C$15
Name tlb_rate: Assumptions!$C$14
Name tlb_turns: Assumptions!$C$10
Name txn_fee_pct: Assumptions!$C$27

Sheet Assumptions
B3: TRANSACTION
B4: Entry multiple (x LTM EBITDA) | C4: 8
B5: Exit multiple (x exit EBITDA) | C5: 8
B6: Hold period (years) | C6: 5
B9: FINANCING
B10: Term Loan B turns (x LTM EBITDA) | C10: 5
B11: Revolver capacity | C11: 25
B12: Revolver margin | C12: 0.09
B13: Revolver commitment fee (undrawn) | C13: 0.005
B14: TLB margin | C14: 0.08
B15: TLB mandatory amortisation (% of original) | C15: 0.01
B16: Excess-cash sweep share | C16: 0.75
B17: Mezzanine turns (x LTM EBITDA) | C17: 1
B18: Mezzanine cash coupon | C18: 0.12
B19: Mezzanine PIK accrual | C19: 0.02
B21: EXISTING BALANCE SHEET
B22: Existing debt (repaid at close) | C22: 55
B23: Existing cash | C23: 10
B24: Minimum cash | C24: 8
B26: FEES
B27: Transaction fees (% of EV) | C27: 0.02
B28: Financing fees (% of funded debt) | C28: 0.025
B30: OPERATING
B31: Tax rate | C31: 0.25
B32: D&A (% of revenue) | C32: 0.045
B33: Δ NWC (% of revenue increase) | C33: 0.15
B35: RETURNS
B36: Hurdle IRR | C36: 0.2

Sheet Operating_Model
A2: Operating model (EUR m) | B2: FY2026 (LTM) | C2: FY2027 | D2: FY2028 | E2: FY2029 | F2: FY2030 | G2: FY2031
B4: Seals revenue | C4: 96
B5: growth % | C5: 0.08 | D5: 0.08 | E5: 0.07 | F5: 0.07 | G5: 0.06
B6: revenue | C6: ==$C$4*(1+C5) | D6: ==C6*(1+D5) | E6: ==D6*(1+E5) | F6: ==E6*(1+F5) | G6: ==F6*(1+G5)
B7: Bearings revenue | C7: 74
B8: growth % | C8: 0.04 | D8: 0.04 | E8: 0.04 | F8: 0.035 | G8: 0.035
B9: revenue | C9: ==$C$7*(1+C8) | D9: ==C9*(1+D8) | E9: ==D9*(1+E8) | F9: ==E9*(1+F8) | G9: ==F9*(1+G8)
B10: Fabrication revenue | C10: 58
B11: growth % | C11: 0.025 | D11: 0.025 | E11: 0.02 | F11: 0.02 | G11: 0.02
B12: revenue | C12: ==$C$10*(1+C11) | D12: ==C12*(1+D11) | E12: ==D12*(1+E11) | F12: ==E12*(1+F11) | G12: ==F12*(1+G11)
B14: Total revenue | C14: ==C6+C9+C12 | D14: ==D6+D9+D12 | E14: ==E6+E9+E12 | F14: ==F6+F9+F12 | G14: ==G6+G9+G12
B15: EBITDA margins
B16: seals margin | C16: 0.264 | D16: 0.268 | E16: 0.272 | F16: 0.276 | G16: 0.28
B17: bearings margin | C17: 0.192 | D17: 0.194 | E17: 0.196 | F17: 0.198 | G17: 0.2
B18: fabrication margin | C18: 0.127 | D18: 0.129 | E18: 0.131 | F18: 0.133 | G18: 0.135
B19: Total EBITDA | C19: ==C6*C16+C9*C17+C12*C18 | D19: ==D6*D16+D9*D17+D12*D18 | E19: ==E6*E16+E9*E17+E12*E18 | F19: ==F6*F16+F9*F17+F12*F18 | G19: ==G6*G16+G9*G17+G12*G18
B21: D&A | C21: ==da_pct*C14 | D21: ==da_pct*D14 | E21: ==da_pct*E14 | F21: ==da_pct*F14 | G21: ==da_pct*G14
B22: EBIT (pre-interest) | C22: ==C19-C21 | D22: ==D19-D21 | E22: ==E19-E21 | F22: ==F19-F21 | G22: ==G19-G21
B23: Capex % of revenue | C23: 0.055 | D23: 0.05 | E23: 0.045 | F23: 0.04 | G23: 0.04
B24: Capex | C24: ==C23*C14 | D24: ==D23*D14 | E24: ==E23*E14 | F24: ==F23*F14 | G24: ==G23*G14
B25: Δ NWC | C25: ==nwc_pct*(C14-B14) | D25: ==nwc_pct*(D14-C14) | E25: ==nwc_pct*(E14-D14) | F25: ==nwc_pct*(F14-E14) | G25: ==nwc_pct*(G14-F14)

Sheet Sources_Uses
A2: Sources & uses at close (EUR m)
B3: Entry EV | C3: ==entry_multiple*Operating_Model!$B$19
B4: Purchase equity value | C4: ==C3-existing_debt+existing_cash
B9: USES
B10: Purchase of equity | C10: ==C4
B11: Repay existing debt | C11: ==existing_debt
B12: Transaction fees | C12: ==txn_fee_pct*C3
B13: Financing fees | C13: ==fin_fee_pct*(C17+C18)
B14: Total uses | C14: ==SUM(C10:C13)
B16: SOURCES
B17: Term Loan B | C17: ==tlb_turns*Operating_Model!$B$19
B18: Mezzanine | C18: ==mezz_turns*Operating_Model!$B$19
B19: Balance-sheet cash used | C19: ==existing_cash-min_cash
B20: Sponsor equity (plug) | C20: ==C14-SUM(C17:C19)
B21: Total sources | C21: ==SUM(C17:C20)
B23: CHECK sources = uses | C23: ==IF(ABS(C21-C14)<0.01,"OK","BREAK")

Sheet Debt_Schedule
A2: Debt schedule (EUR m) | B2: At close | C2: ==Operating_Model!C19 | D2: ==Operating_Model!D19 | E2: ==Operating_Model!E19 | F2: ==Operating_Model!F19 | G2: ==Operating_Model!G19
C3: ==Operating_Model!C21 | D3: ==Operating_Model!D21 | E3: ==Operating_Model!E21 | F3: ==Operating_Model!F21 | G3: ==Operating_Model!G21
B5: Term loan B
B6: ==Sources_Uses!C17 | C6: ==B6 | D6: ==C10 | E6: ==D10 | F6: ==E10 | G6: ==F10
B7: Interest | C7: ==tlb_rate*C6 | D7: ==tlb_rate*D6 | E7: ==tlb_rate*E6 | F7: ==tlb_rate*F6 | G7: ==tlb_rate*G6
B8: Mandatory amortisation | C8: ==MIN(tlb_amort_pct*Sources_Uses!$C$17,C6) | D8: ==MIN(tlb_amort_pct*Sources_Uses!$C$17,D6) | E8: ==MIN(tlb_amort_pct*Sources_Uses!$C$17,E6) | F8: ==MIN(tlb_amort_pct*Sources_Uses!$C$17,F6) | G8: ==MIN(tlb_amort_pct*Sources_Uses!$C$17,G6)
B9: Cash sweep | C9: ==MIN(cash_sweep_pct*MAX(0,C35-C8),C6-C8) | D9: ==MIN(cash_sweep_pct*MAX(0,D35-D8),D6-D8) | E9: ==MIN(cash_sweep_pct*MAX(0,E35-E8),E6-E8) | F9: ==MIN(cash_sweep_pct*MAX(0,F35-F8),F6-F8) | G9: ==MIN(cash_sweep_pct*MAX(0,G35-G8),G6-G8)
B10: Ending | C10: ==C6-C8-C9 | D10: ==D6-D8-D9 | E10: ==E6-E8-E9 | F10: ==F6-F8-F9 | G10: ==G6-G8-G9
B12: Mezzanine
B13: ==Sources_Uses!C18 | C13: ==B13 | D13: ==C16 | E13: ==D16 | F13: ==E16 | G13: ==F16
B14: Cash interest | C14: ==mezz_cash_rate*C13 | D14: ==mezz_cash_rate*D13 | E14: ==mezz_cash_rate*E13 | F14: ==mezz_cash_rate*F13 | G14: ==mezz_cash_rate*G13
B15: PIK accrual | C15: ==C13*mezz_pik_rate | D15: ==D13*mezz_pik_rate | E15: ==E13*mezz_pik_rate | F15: ==F13*mezz_pik_rate | G15: ==G13*mezz_pik_rate
B16: Ending | C16: ==C13+C15 | D16: ==D13+D15 | E16: ==E13+E15 | F16: ==F13+F15 | G16: ==G13+G15
B18: Revolver
B19: 0 | C19: ==B19 | D19: ==C25 | E19: ==D25 | F19: ==E25 | G19: ==F25
B20: Interest | C20: ==revolver_rate*C19 | D20: ==revolver_rate*D19 | E20: ==revolver_rate*E19 | F20: ==revolver_rate*F19 | G20: ==revolver_rate*G19
B21: Commitment fee (undrawn) | C21: ==commitment_fee*MAX(0,revolver_capacity-C19) | D21: ==commitment_fee*MAX(0,revolver_capacity-D19) | E21: ==commitment_fee*MAX(0,revolver_capacity-E19) | F21: ==commitment_fee*MAX(0,revolver_capacity-F19) | G21: ==commitment_fee*MAX(0,revolver_capacity-G19)
B22: Repayment | C22: ==MIN(C19,MAX(0,C35)) | D22: ==MIN(D19,MAX(0,D35)) | E22: ==MIN(E19,MAX(0,E35)) | F22: ==MIN(F19,MAX(0,F35)) | G22: ==MIN(G19,MAX(0,G35))
B23: Draw (deficit) | C23: ==MIN(MAX(0,revolver_capacity-C19),MAX(0,-C35)) | D23: ==MIN(MAX(0,revolver_capacity-D19),MAX(0,-D35)) | E23: ==MIN(MAX(0,revolver_capacity-E19),MAX(0,-E35)) | F23: ==MIN(MAX(0,revolver_capacity-F19),MAX(0,-F35)) | G23: ==MIN(MAX(0,revolver_capacity-G19),MAX(0,-G35))
B24: Draw (top-up after amort) | C24: ==MIN(MAX(0,revolver_capacity-(C19+C23)),MAX(0,-(C35-C22+C23-C8))) | D24: ==MIN(MAX(0,revolver_capacity-(D19+D23)),MAX(0,-(D35-D22+D23-D8))) | E24: ==MIN(MAX(0,revolver_capacity-(E19+E23)),MAX(0,-(E35-E22+E23-E8))) | F24: ==MIN(MAX(0,revolver_capacity-(F19+F23)),MAX(0,-(F35-F22+F23-F8))) | G24: ==MIN(MAX(0,revolver_capacity-(G19+G23)),MAX(0,-(G35-G22+G23-G8)))
B25: Ending | C25: ==C19+C23+C24-C22 | D25: ==D19+D23+D24-D22 | E25: ==E19+E23+E24-E22 | F25: ==F19+F23+F24-F22 | G25: ==G19+G23+G24-G22
B27: Cash flow
B28: Total cash interest | C28: ==C7+C14+C20+C21 | D28: ==D7+D14+D20+D21 | E28: ==E7+E14+E20+E21 | F28: ==F7+F14+F20+F21 | G28: ==G7+G14+G20+G21
B29: EBT | C29: ==C2-C3-C28 | D29: ==D2-D3-D28 | E29: ==E2-E3-E28 | F29: ==F2-F3-F28 | G29: ==G2-G3-G28
B30: Taxes | C30: ==MAX(0,C29*tax_rate) | D30: ==MAX(0,D29*tax_rate) | E30: ==MAX(0,E29*tax_rate) | F30: ==MAX(0,F29*tax_rate) | G30: ==MAX(0,G29*tax_rate)
B31: Net income | C31: ==C29-C30 | D31: ==D29-D30 | E31: ==E29-E30 | F31: ==F29-F30 | G31: ==G29-G30
B35: CFADR | C35: ==C31+C3-Operating_Model!C24-Operating_Model!C25 | D35: ==D31+D3-Operating_Model!D24-Operating_Model!D25 | E35: ==E31+E3-Operating_Model!E24-Operating_Model!E25 | F35: ==F31+F3-Operating_Model!F24-Operating_Model!F25 | G35: ==G31+G3-Operating_Model!G24-Operating_Model!G25
B36: Residual (post revolver + amort) | C36: ==C35-C22+C23+C24-C8 | D36: ==D35-D22+D23+D24-D8 | E36: ==E35-E22+E23+E24-E8 | F36: ==F35-F22+F23+F24-F8 | G36: ==G35-G22+G23+G24-G8
B38: Retained to cash | C38: ==C36-C9 | D38: ==D36-D9 | E38: ==E36-E9 | F38: ==F36-F9 | G38: ==G36-G9
B40: ==min_cash | C40: ==B40 | D40: ==C41 | E40: ==D41 | F40: ==E41 | G40: ==F41
B41: Cash — ending | C41: ==C40+C38 | D41: ==D40+D38 | E41: ==E40+E38 | F41: ==F40+F38 | G41: ==G40+G38
B43: Credit stats
B44: Net debt | C44: ==C10+C16+C25-C41 | D44: ==D10+D16+D25-D41 | E44: ==E10+E16+E25-E41 | F44: ==F10+F16+F25-F41 | G44: ==G10+G16+G25-G41
B45: Leverage (x) | C45: ==C44/C2 | D45: ==D44/D2 | E45: ==E44/E2 | F45: ==F44/F2 | G45: ==G44/G2
B46: Coverage (x) | C46: ==C2/C28 | D46: ==D2/D28 | E46: ==E2/E28 | F46: ==F2/F28 | G46: ==G2/G28

Sheet Debt_Schedule_Avg
A2: Debt schedule (EUR m) — average-balance interest (ITERATIVE/CIRCULAR) | B2: At close | C2: ==Operating_Model!C19 | D2: ==Operating_Model!D19 | E2: ==Operating_Model!E19 | F2: ==Operating_Model!F19 | G2: ==Operating_Model!G19
C3: ==Operating_Model!C21 | D3: ==Operating_Model!D21 | E3: ==Operating_Model!E21 | F3: ==Operating_Model!F21 | G3: ==Operating_Model!G21
B5: Term loan B
B6: ==Sources_Uses!C17 | C6: ==B6 | D6: ==C10 | E6: ==D10 | F6: ==E10 | G6: ==F10
B7: Interest | C7: ==tlb_rate*(C6+C10)/2 | D7: ==tlb_rate*(D6+D10)/2 | E7: ==tlb_rate*(E6+E10)/2 | F7: ==tlb_rate*(F6+F10)/2 | G7: ==tlb_rate*(G6+G10)/2
B8: Mandatory amortisation | C8: ==MIN(tlb_amort_pct*Sources_Uses!$C$17,C6) | D8: ==MIN(tlb_amort_pct*Sources_Uses!$C$17,D6) | E8: ==MIN(tlb_amort_pct*Sources_Uses!$C$17,E6) | F8: ==MIN(tlb_amort_pct*Sources_Uses!$C$17,F6) | G8: ==MIN(tlb_amort_pct*Sources_Uses!$C$17,G6)
B9: Cash sweep | C9: ==MIN(cash_sweep_pct*MAX(0,C35-C8),C6-C8) | D9: ==MIN(cash_sweep_pct*MAX(0,D35-D8),D6-D8) | E9: ==MIN(cash_sweep_pct*MAX(0,E35-E8),E6-E8) | F9: ==MIN(cash_sweep_pct*MAX(0,F35-F8),F6-F8) | G9: ==MIN(cash_sweep_pct*MAX(0,G35-G8),G6-G8)
B10: Ending | C10: ==C6-C8-C9 | D10: ==D6-D8-D9 | E10: ==E6-E8-E9 | F10: ==F6-F8-F9 | G10: ==G6-G8-G9
B12: Mezzanine
B13: ==Sources_Uses!C18 | C13: ==B13 | D13: ==C16 | E13: ==D16 | F13: ==E16 | G13: ==F16
B14: Cash interest | C14: ==mezz_cash_rate*(C13+C16)/2 | D14: ==mezz_cash_rate*(D13+D16)/2 | E14: ==mezz_cash_rate*(E13+E16)/2 | F14: ==mezz_cash_rate*(F13+F16)/2 | G14: ==mezz_cash_rate*(G13+G16)/2
B15: PIK accrual | C15: ==C13*mezz_pik_rate | D15: ==D13*mezz_pik_rate | E15: ==E13*mezz_pik_rate | F15: ==F13*mezz_pik_rate | G15: ==G13*mezz_pik_rate
B16: Ending | C16: ==C13+C15 | D16: ==D13+D15 | E16: ==E13+E15 | F16: ==F13+F15 | G16: ==G13+G15
B18: Revolver
B19: 0 | C19: ==B19 | D19: ==C25 | E19: ==D25 | F19: ==E25 | G19: ==F25
B20: Interest | C20: ==revolver_rate*(C19+C25)/2 | D20: ==revolver_rate*(D19+D25)/2 | E20: ==revolver_rate*(E19+E25)/2 | F20: ==revolver_rate*(F19+F25)/2 | G20: ==revolver_rate*(G19+G25)/2
B21: Commitment fee (undrawn) | C21: ==commitment_fee*MAX(0,(revolver_capacity-C19+revolver_capacity-C25)/2) | D21: ==commitment_fee*MAX(0,(revolver_capacity-D19+revolver_capacity-D25)/2) | E21: ==commitment_fee*MAX(0,(revolver_capacity-E19+revolver_capacity-E25)/2) | F21: ==commitment_fee*MAX(0,(revolver_capacity-F19+revolver_capacity-F25)/2) | G21: ==commitment_fee*MAX(0,(revolver_capacity-G19+revolver_capacity-G25)/2)
B22: Repayment | C22: ==MIN(C19,MAX(0,C35)) | D22: ==MIN(D19,MAX(0,D35)) | E22: ==MIN(E19,MAX(0,E35)) | F22: ==MIN(F19,MAX(0,F35)) | G22: ==MIN(G19,MAX(0,G35))
B23: Draw (deficit) | C23: ==MIN(MAX(0,revolver_capacity-C19),MAX(0,-C35)) | D23: ==MIN(MAX(0,revolver_capacity-D19),MAX(0,-D35)) | E23: ==MIN(MAX(0,revolver_capacity-E19),MAX(0,-E35)) | F23: ==MIN(MAX(0,revolver_capacity-F19),MAX(0,-F35)) | G23: ==MIN(MAX(0,revolver_capacity-G19),MAX(0,-G35))
B24: Draw (top-up after amort) | C24: ==MIN(MAX(0,revolver_capacity-(C19+C23)),MAX(0,-(C35-C22+C23-C8))) | D24: ==MIN(MAX(0,revolver_capacity-(D19+D23)),MAX(0,-(D35-D22+D23-D8))) | E24: ==MIN(MAX(0,revolver_capacity-(E19+E23)),MAX(0,-(E35-E22+E23-E8))) | F24: ==MIN(MAX(0,revolver_capacity-(F19+F23)),MAX(0,-(F35-F22+F23-F8))) | G24: ==MIN(MAX(0,revolver_capacity-(G19+G23)),MAX(0,-(G35-G22+G23-G8)))
B25: Ending | C25: ==C19+C23+C24-C22 | D25: ==D19+D23+D24-D22 | E25: ==E19+E23+E24-E22 | F25: ==F19+F23+F24-F22 | G25: ==G19+G23+G24-G22
B27: Cash flow
B28: Total cash interest | C28: ==C7+C14+C20+C21 | D28: ==D7+D14+D20+D21 | E28: ==E7+E14+E20+E21 | F28: ==F7+F14+F20+F21 | G28: ==G7+G14+G20+G21
B29: EBT | C29: ==C2-C3-C28 | D29: ==D2-D3-D28 | E29: ==E2-E3-E28 | F29: ==F2-F3-F28 | G29: ==G2-G3-G28
B30: Taxes | C30: ==MAX(0,C29*tax_rate) | D30: ==MAX(0,D29*tax_rate) | E30: ==MAX(0,E29*tax_rate) | F30: ==MAX(0,F29*tax_rate) | G30: ==MAX(0,G29*tax_rate)
B31: Net income | C31: ==C29-C30 | D31: ==D29-D30 | E31: ==E29-E30 | F31: ==F29-F30 | G31: ==G29-G30
B35: CFADR | C35: ==C31+C3-Operating_Model!C24-Operating_Model!C25 | D35: ==D31+D3-Operating_Model!D24-Operating_Model!D25 | E35: ==E31+E3-Operating_Model!E24-Operating_Model!E25 | F35: ==F31+F3-Operating_Model!F24-Operating_Model!F25 | G35: ==G31+G3-Operating_Model!G24-Operating_Model!G25
B36: Residual (post revolver + amort) | C36: ==C35-C22+C23+C24-C8 | D36: ==D35-D22+D23+D24-D8 | E36: ==E35-E22+E23+E24-E8 | F36: ==F35-F22+F23+F24-F8 | G36: ==G35-G22+G23+G24-G8
B38: Retained to cash | C38: ==C36-C9 | D38: ==D36-D9 | E38: ==E36-E9 | F38: ==F36-F9 | G38: ==G36-G9
B40: ==min_cash | C40: ==B40 | D40: ==C41 | E40: ==D41 | F40: ==E41 | G40: ==F41
B41: Cash — ending | C41: ==C40+C38 | D41: ==D40+D38 | E41: ==E40+E38 | F41: ==F40+F38 | G41: ==G40+G38
B43: Credit stats
B44: Net debt | C44: ==C10+C16+C25-C41 | D44: ==D10+D16+D25-D41 | E44: ==E10+E16+E25-E41 | F44: ==F10+F16+F25-F41 | G44: ==G10+G16+G25-G41
B45: Leverage (x) | C45: ==C44/C2 | D45: ==D44/D2 | E45: ==E44/E2 | F45: ==F44/F2 | G45: ==G44/G2
B46: Coverage (x) | C46: ==C2/C28 | D46: ==D2/D28 | E46: ==E2/E28 | F46: ==F2/F28 | G46: ==G2/G28

Sheet Sens_Models
A2: Sensitivity engine: full model re-run per TLB leverage case (no data table)
B4: Leverage case 4.0x TLB
B5: 4 | C5: TLB at close
B6: ==(Sources_Uses!$C$10+Sources_Uses!$C$11+Sources_Uses!$C$12+fin_fee_pct*(B5+Sources_Uses!$C$18))-B5-Sources_Uses!$C$18-Sources_Uses!$C$19 | C6: Sponsor equity
B7: year → | C7: FY2027 | D7: FY2028 | E7: FY2029 | F7: FY2030 | G7: FY2031
B8: TLB beginning | C8: ==$B$5 | D8: ==C14 | E8: ==D14 | F8: ==E14 | G8: ==F14
B9: Cash interest | C9: ==tlb_rate*C8+mezz_cash_rate*Sources_Uses!$C$18+commitment_fee*revolver_capacity | D9: ==tlb_rate*D8+mezz_cash_rate*Sources_Uses!$C$18+commitment_fee*revolver_capacity | E9: ==tlb_rate*E8+mezz_cash_rate*Sources_Uses!$C$18+commitment_fee*revolver_capacity | F9: ==tlb_rate*F8+mezz_cash_rate*Sources_Uses!$C$18+commitment_fee*revolver_capacity | G9: ==tlb_rate*G8+mezz_cash_rate*Sources_Uses!$C$18+commitment_fee*revolver_capacity
B10: CFADR | C10: ==(Operating_Model!C$19-Operating_Model!C$21-C9)*(1-tax_rate)+Operating_Model!C$21-Operating_Model!C$24-Operating_Model!C$25 | D10: ==(Operating_Model!D$19-Operating_Model!D$21-D9)*(1-tax_rate)+Operating_Model!D$21-Operating_Model!D$24-Operating_Model!D$25 | E10: ==(Operating_Model!E$19-Operating_Model!E$21-E9)*(1-tax_rate)+Operating_Model!E$21-Operating_Model!E$24-Operating_Model!E$25 | F10: ==(Operating_Model!F$19-Operating_Model!F$21-F9)*(1-tax_rate)+Operating_Model!F$21-Operating_Model!F$24-Operating_Model!F$25 | G10: ==(Operating_Model!G$19-Operating_Model!G$21-G9)*(1-tax_rate)+Operating_Model!G$21-Operating_Model!G$24-Operating_Model!G$25
B11: Mandatory | C11: ==MIN(tlb_amort_pct*$B$5,C8) | D11: ==MIN(tlb_amort_pct*$B$5,D8) | E11: ==MIN(tlb_amort_pct*$B$5,E8) | F11: ==MIN(tlb_amort_pct*$B$5,F8) | G11: ==MIN(tlb_amort_pct*$B$5,G8)
B12: Sweep | C12: ==MIN(cash_sweep_pct*MAX(0,C10-C11),C8-C11) | D12: ==MIN(cash_sweep_pct*MAX(0,D10-D11),D8-D11) | E12: ==MIN(cash_sweep_pct*MAX(0,E10-E11),E8-E11) | F12: ==MIN(cash_sweep_pct*MAX(0,F10-F11),F8-F11) | G12: ==MIN(cash_sweep_pct*MAX(0,G10-G11),G8-G11)
B13: Retained | C13: ==C10-C11-C12 | D13: ==D10-D11-D12 | E13: ==E10-E11-E12 | F13: ==F10-F11-F12 | G13: ==G10-G11-G12
B14: TLB ending | C14: ==C8-C11-C12 | D14: ==D8-D11-D12 | E14: ==E8-E11-E12 | F14: ==F8-F11-F12 | G14: ==G8-G11-G12
B15: Cash ending | C15: ==min_cash+SUM(C13:G13)
B16: Mezzanine at exit | C16: ==Sources_Uses!$C$18*(1+mezz_pik_rate)^hold_years
B17: Net debt at exit | C17: ==G14+C16-C15
B19: Leverage case 4.5x TLB
B20: 4.5 | C20: TLB at close
B21: ==(Sources_Uses!$C$10+Sources_Uses!$C$11+Sources_Uses!$C$12+fin_fee_pct*(B20+Sources_Uses!$C$18))-B20-Sources_Uses!$C$18-Sources_Uses!$C$19 | C21: Sponsor equity
B22: year → | C22: FY2027 | D22: FY2028 | E22: FY2029 | F22: FY2030 | G22: FY2031
B23: TLB beginning | C23: ==$B$20 | D23: ==C29 | E23: ==D29 | F23: ==E29 | G23: ==F29
B24: Cash interest | C24: ==tlb_rate*C23+mezz_cash_rate*Sources_Uses!$C$18+commitment_fee*revolver_capacity | D24: ==tlb_rate*D23+mezz_cash_rate*Sources_Uses!$C$18+commitment_fee*revolver_capacity | E24: ==tlb_rate*E23+mezz_cash_rate*Sources_Uses!$C$18+commitment_fee*revolver_capacity | F24: ==tlb_rate*F23+mezz_cash_rate*Sources_Uses!$C$18+commitment_fee*revolver_capacity | G24: ==tlb_rate*G23+mezz_cash_rate*Sources_Uses!$C$18+commitment_fee*revolver_capacity
B25: CFADR | C25: ==(Operating_Model!C$19-Operating_Model!C$21-C24)*(1-tax_rate)+Operating_Model!C$21-Operating_Model!C$24-Operating_Model!C$25 | D25: ==(Operating_Model!D$19-Operating_Model!D$21-D24)*(1-tax_rate)+Operating_Model!D$21-Operating_Model!D$24-Operating_Model!D$25 | E25: ==(Operating_Model!E$19-Operating_Model!E$21-E24)*(1-tax_rate)+Operating_Model!E$21-Operating_Model!E$24-Operating_Model!E$25 | F25: ==(Operating_Model!F$19-Operating_Model!F$21-F24)*(1-tax_rate)+Operating_Model!F$21-Operating_Model!F$24-Operating_Model!F$25 | G25: ==(Operating_Model!G$19-Operating_Model!G$21-G24)*(1-tax_rate)+Operating_Model!G$21-Operating_Model!G$24-Operating_Model!G$25
B26: Mandatory | C26: ==MIN(tlb_amort_pct*$B$20,C23) | D26: ==MIN(tlb_amort_pct*$B$20,D23) | E26: ==MIN(tlb_amort_pct*$B$20,E23) | F26: ==MIN(tlb_amort_pct*$B$20,F23) | G26: ==MIN(tlb_amort_pct*$B$20,G23)
B27: Sweep | C27: ==MIN(cash_sweep_pct*MAX(0,C25-C26),C23-C26) | D27: ==MIN(cash_sweep_pct*MAX(0,D25-D26),D23-D26) | E27: ==MIN(cash_sweep_pct*MAX(0,E25-E26),E23-E26) | F27: ==MIN(cash_sweep_pct*MAX(0,F25-F26),F23-F26) | G27: ==MIN(cash_sweep_pct*MAX(0,G25-G26),G23-G26)
B28: Retained | C28: ==C25-C26-C27 | D28: ==D25-D26-D27 | E28: ==E25-E26-E27 | F28: ==F25-F26-F27 | G28: ==G25-G26-G27
B29: TLB ending | C29: ==C23-C26-C27 | D29: ==D23-D26-D27 | E29: ==E23-E26-E27 | F29: ==F23-F26-F27 | G29: ==G23-G26-G27
B30: Cash ending | C30: ==min_cash+SUM(C28:G28)
B31: Mezzanine at exit | C31: ==Sources_Uses!$C$18*(1+mezz_pik_rate)^hold_years
B32: Net debt at exit | C32: ==G29+C31-C30
B34: Leverage case 5.0x TLB
B35: 5 | C35: TLB at close
B36: ==(Sources_Uses!$C$10+Sources_Uses!$C$11+Sources_Uses!$C$12+fin_fee_pct*(B35+Sources_Uses!$C$18))-B35-Sources_Uses!$C$18-Sources_Uses!$C$19 | C36: Sponsor equity
B37: year → | C37: FY2027 | D37: FY2028 | E37: FY2029 | F37: FY2030 | G37: FY2031
B38: TLB beginning | C38: ==$B$35 | D38: ==C44 | E38: ==D44 | F38: ==E44 | G38: ==F44
B39: Cash interest | C39: ==tlb_rate*C38+mezz_cash_rate*Sources_Uses!$C$18+commitment_fee*revolver_capacity | D39: ==tlb_rate*D38+mezz_cash_rate*Sources_Uses!$C$18+commitment_fee*revolver_capacity | E39: ==tlb_rate*E38+mezz_cash_rate*Sources_Uses!$C$18+commitment_fee*revolver_capacity | F39: ==tlb_rate*F38+mezz_cash_rate*Sources_Uses!$C$18+commitment_fee*revolver_capacity | G39: ==tlb_rate*G38+mezz_cash_rate*Sources_Uses!$C$18+commitment_fee*revolver_capacity
B40: CFADR | C40: ==(Operating_Model!C$19-Operating_Model!C$21-C39)*(1-tax_rate)+Operating_Model!C$21-Operating_Model!C$24-Operating_Model!C$25 | D40: ==(Operating_Model!D$19-Operating_Model!D$21-D39)*(1-tax_rate)+Operating_Model!D$21-Operating_Model!D$24-Operating_Model!D$25 | E40: ==(Operating_Model!E$19-Operating_Model!E$21-E39)*(1-tax_rate)+Operating_Model!E$21-Operating_Model!E$24-Operating_Model!E$25 | F40: ==(Operating_Model!F$19-Operating_Model!F$21-F39)*(1-tax_rate)+Operating_Model!F$21-Operating_Model!F$24-Operating_Model!F$25 | G40: ==(Operating_Model!G$19-Operating_Model!G$21-G39)*(1-tax_rate)+Operating_Model!G$21-Operating_Model!G$24-Operating_Model!G$25
B41: Mandatory | C41: ==MIN(tlb_amort_pct*$B$35,C38) | D41: ==MIN(tlb_amort_pct*$B$35,D38) | E41: ==MIN(tlb_amort_pct*$B$35,E38) | F41: ==MIN(tlb_amort_pct*$B$35,F38) | G41: ==MIN(tlb_amort_pct*$B$35,G38)
B42: Sweep | C42: ==MIN(cash_sweep_pct*MAX(0,C40-C41),C38-C41) | D42: ==MIN(cash_sweep_pct*MAX(0,D40-D41),D38-D41) | E42: ==MIN(cash_sweep_pct*MAX(0,E40-E41),E38-E41) | F42: ==MIN(cash_sweep_pct*MAX(0,F40-F41),F38-F41) | G42: ==MIN(cash_sweep_pct*MAX(0,G40-G41),G38-G41)
B43: Retained | C43: ==C40-C41-C42 | D43: ==D40-D41-D42 | E43: ==E40-E41-E42 | F43: ==F40-F41-F42 | G43: ==G40-G41-G42
B44: TLB ending | C44: ==C38-C41-C42 | D44: ==D38-D41-D42 | E44: ==E38-E41-E42 | F44: ==F38-F41-F42 | G44: ==G38-G41-G42
...

Sheet Returns
A2: Returns (EUR m)
B3: Exit-year EBITDA | C3: ==Debt_Schedule!G2
B4: Exit multiple | C4: ==exit_multiple
B5: Exit EV | C5: ==C3*C4
B6: Net debt at exit | C6: ==Debt_Schedule!G44
B7: Exit equity to sponsor | C7: ==C5-C6
B8: Sponsor equity at entry | C8: ==Sources_Uses!C20
B9: MOIC (x) | C9: ==C7/C8
B11: Sponsor cash flows
B12: ==-C8 | C12: 0 | D12: 0 | E12: 0 | F12: 0 | G12: ==C7
B13: Sponsor IRR | C13: ==IRR(B12:G12)
B14: ==-C8 | C14: 0 | D14: 0 | E14: 0 | F14: 0 | G14: ==C5-Debt_Schedule_Avg!G44
B15: Sponsor IRR (avg-balance interest) | C15: ==IRR(B14:G14)
B16: Breakeven exit multiple (goal seek: IRR = hurdle) | C16: 7.5420183 | D16: ← static value; in Excel: Data → What-If Analysis → Goal Seek
A18: Sensitivity: sponsor IRR by exit multiple (rows) × TLB leverage (columns) | B18: exit multiple ↓ / TLB turns →
C19: 4 | D19: 4.5 | E19: 5 | F19: 5.5 | G19: 6
B20: 7 | C20: ==POWER(($B20*$C$3-Sens_Models!$C$17)/Sens_Models!$B$6,1/hold_years)-1 | D20: ==POWER(($B20*$C$3-Sens_Models!$C$32)/Sens_Models!$B$21,1/hold_years)-1 | E20: ==POWER(($B20*$C$3-Sens_Models!$C$47)/Sens_Models!$B$36,1/hold_years)-1 | F20: ==POWER(($B20*$C$3-Sens_Models!$C$62)/Sens_Models!$B$51,1/hold_years)-1 | G20: ==POWER(($B20*$C$3-Sens_Models!$C$77)/Sens_Models!$B$66,1/hold_years)-1
B21: 7.5 | C21: ==POWER(($B21*$C$3-Sens_Models!$C$17)/Sens_Models!$B$6,1/hold_years)-1 | D21: ==POWER(($B21*$C$3-Sens_Models!$C$32)/Sens_Models!$B$21,1/hold_years)-1 | E21: ==POWER(($B21*$C$3-Sens_Models!$C$47)/Sens_Models!$B$36,1/hold_years)-1 | F21: ==POWER(($B21*$C$3-Sens_Models!$C$62)/Sens_Models!$B$51,1/hold_years)-1 | G21: ==POWER(($B21*$C$3-Sens_Models!$C$77)/Sens_Models!$B$66,1/hold_years)-1
B22: 8 | C22: ==POWER(($B22*$C$3-Sens_Models!$C$17)/Sens_Models!$B$6,1/hold_years)-1 | D22: ==POWER(($B22*$C$3-Sens_Models!$C$32)/Sens_Models!$B$21,1/hold_years)-1 | E22: ==POWER(($B22*$C$3-Sens_Models!$C$47)/Sens_Models!$B$36,1/hold_years)-1 | F22: ==POWER(($B22*$C$3-Sens_Models!$C$62)/Sens_Models!$B$51,1/hold_years)-1 | G22: ==POWER(($B22*$C$3-Sens_Models!$C$77)/Sens_Models!$B$66,1/hold_years)-1
B23: 8.5 | C23: ==POWER(($B23*$C$3-Sens_Models!$C$17)/Sens_Models!$B$6,1/hold_years)-1 | D23: ==POWER(($B23*$C$3-Sens_Models!$C$32)/Sens_Models!$B$21,1/hold_years)-1 | E23: ==POWER(($B23*$C$3-Sens_Models!$C$47)/Sens_Models!$B$36,1/hold_years)-1 | F23: ==POWER(($B23*$C$3-Sens_Models!$C$62)/Sens_Models!$B$51,1/hold_years)-1 | G23: ==POWER(($B23*$C$3-Sens_Models!$C$77)/Sens_Models!$B$66,1/hold_years)-1
B24: 9 | C24: ==POWER(($B24*$C$3-Sens_Models!$C$17)/Sens_Models!$B$6,1/hold_years)-1 | D24: ==POWER(($B24*$C$3-Sens_Models!$C$32)/Sens_Models!$B$21,1/hold_years)-1 | E24: ==POWER(($B24*$C$3-Sens_Models!$C$47)/Sens_Models!$B$36,1/hold_years)-1 | F24: ==POWER(($B24*$C$3-Sens_Models!$C$62)/Sens_Models!$B$51,1/hold_years)-1 | G24: ==POWER(($B24*$C$3-Sens_Models!$C$77)/Sens_Models!$B$66,1/hold_years)-1
A26: Base case (8.0x / 5.0x) must equal C13 — the hand-rolled grid's own check

Sheet Checks
A2: Model checks — the IF(...,"OK","BREAK") convention
A3: Sources = uses | B3: ==IF(ABS(Sources_Uses!C21-Sources_Uses!C14)<0.01,"OK","BREAK")
A4: TLB roll-forward | C4: ==IF(ABS(Debt_Schedule!C10-(Debt_Schedule!C6-Debt_Schedule!C8-Debt_Schedule!C9))<0.005,"OK","BREAK") | D4: ==IF(ABS(Debt_Schedule!D10-(Debt_Schedule!D6-Debt_Schedule!D8-Debt_Schedule!D9))<0.005,"OK","BREAK") | E4: ==IF(ABS(Debt_Schedule!E10-(Debt_Schedule!E6-Debt_Schedule!E8-Debt_Schedule!E9))<0.005,"OK","BREAK") | F4: ==IF(ABS(Debt_Schedule!F10-(Debt_Schedule!F6-Debt_Schedule!F8-Debt_Schedule!F9))<0.005,"OK","BREAK") | G4: ==IF(ABS(Debt_Schedule!G10-(Debt_Schedule!G6-Debt_Schedule!G8-Debt_Schedule!G9))<0.005,"OK","BREAK")
A5: Mezzanine roll-forward (PIK) | C5: ==IF(ABS(Debt_Schedule!C16-(Debt_Schedule!C13+Debt_Schedule!C15))<0.005,"OK","BREAK") | D5: ==IF(ABS(Debt_Schedule!D16-(Debt_Schedule!D13+Debt_Schedule!D15))<0.005,"OK","BREAK") | E5: ==IF(ABS(Debt_Schedule!E16-(Debt_Schedule!E13+Debt_Schedule!E15))<0.005,"OK","BREAK") | F5: ==IF(ABS(Debt_Schedule!F16-(Debt_Schedule!F13+Debt_Schedule!F15))<0.005,"OK","BREAK") | G5: ==IF(ABS(Debt_Schedule!G16-(Debt_Schedule!G13+Debt_Schedule!G15))<0.005,"OK","BREAK")
A6: Revolver roll-forward | C6: ==IF(ABS(Debt_Schedule!C25-(Debt_Schedule!C19+Debt_Schedule!C23+Debt_Schedule!C24-Debt_Schedule!C22))<0.005,"OK","BREAK") | D6: ==IF(ABS(Debt_Schedule!D25-(Debt_Schedule!D19+Debt_Schedule!D23+Debt_Schedule!D24-Debt_Schedule!D22))<0.005,"OK","BREAK") | E6: ==IF(ABS(Debt_Schedule!E25-(Debt_Schedule!E19+Debt_Schedule!E23+Debt_Schedule!E24-Debt_Schedule!E22))<0.005,"OK","BREAK") | F6: ==IF(ABS(Debt_Schedule!F25-(Debt_Schedule!F19+Debt_Schedule!F23+Debt_Schedule!F24-Debt_Schedule!F22))<0.005,"OK","BREAK") | G6: ==IF(ABS(Debt_Schedule!G25-(Debt_Schedule!G19+Debt_Schedule!G23+Debt_Schedule!G24-Debt_Schedule!G22))<0.005,"OK","BREAK")
A7: Cash roll-forward | C7: ==IF(ABS(Debt_Schedule!C41-(Debt_Schedule!C40+Debt_Schedule!C38))<0.005,"OK","BREAK") | D7: ==IF(ABS(Debt_Schedule!D41-(Debt_Schedule!D40+Debt_Schedule!D38))<0.005,"OK","BREAK") | E7: ==IF(ABS(Debt_Schedule!E41-(Debt_Schedule!E40+Debt_Schedule!E38))<0.005,"OK","BREAK") | F7: ==IF(ABS(Debt_Schedule!F41-(Debt_Schedule!F40+Debt_Schedule!F38))<0.005,"OK","BREAK") | G7: ==IF(ABS(Debt_Schedule!G41-(Debt_Schedule!G40+Debt_Schedule!G38))<0.005,"OK","BREAK")
A8: Leverage covenant | B8: ==IF(MAX(Debt_Schedule!C45:G45)<=6.0,"OK","BREACH")
A9: Coverage covenant | B9: ==IF(MIN(Debt_Schedule!C46:G46)>=2.0,"OK","BREACH")
A10: Liquidity: cash ≥ minimum | B10: ==IF(MIN(Debt_Schedule!C41:G41)>=min_cash,"OK","BREACH")
A11: Base IRR ≥ hurdle | B11: ==IF(Returns!C13>=hurdle_irr,"PASS","FAIL")
